<?xml version="1.0" ?>
<sdf version="1.8">
  <world name="turtlebot3_world">

    <!-- Physics: 50 Hz is sufficient for TurtleBot3 at NAV2 speeds (0.2-0.5 m/s).
         Halving from 100 Hz saves ~40% of physics thread CPU. -->
    <physics name="50hz" type="ignored">
      <max_step_size>0.02</max_step_size>
      <real_time_factor>1.0</real_time_factor>
      <real_time_update_rate>50</real_time_update_rate>
    </physics>

    <!-- World system plugins -->
    <plugin filename="gz-sim-physics-system"             name="gz::sim::systems::Physics"/>
    <plugin filename="gz-sim-scene-broadcaster-system"   name="gz::sim::systems::SceneBroadcaster"/>
    <plugin filename="gz-sim-user-commands-system"       name="gz::sim::systems::UserCommands"/>
    <!-- Sensors system: must use ignition- prefix for ign gazebo 6 plugin search path -->
    <plugin filename="ignition-gazebo-sensors-system"    name="ignition::gazebo::systems::Sensors">
      <render_engine>ogre2</render_engine>
    </plugin>
    <plugin filename="ignition-gazebo-imu-system"        name="ignition::gazebo::systems::Imu"/>
    <plugin filename="gz-sim-contact-system"             name="gz::sim::systems::Contact"/>

    <!-- Lighting -->
    <light type="directional" name="sun">
      <cast_shadows>true</cast_shadows>
      <pose>0 0 10 0 0 0</pose>
      <diffuse>0.8 0.8 0.8 1</diffuse>
      <specular>0.2 0.2 0.2 1</specular>
      <direction>-0.5 0.1 -0.9</direction>
    </light>

    <!-- Ground plane -->
    <model name="ground_plane">
      <static>true</static>
      <link name="link">
        <collision name="collision">
          <geometry><plane><normal>0 0 1</normal><size>100 100</size></plane></geometry>
        </collision>
        <visual name="visual">
          <geometry><plane><normal>0 0 1</normal><size>100 100</size></plane></geometry>
          <material>
            <ambient>0.8 0.8 0.8 1</ambient>
            <diffuse>0.8 0.8 0.8 1</diffuse>
          </material>
        </visual>
      </link>
    </model>

    <!-- Outer walls: 6m x 6m room -->
    <model name="wall_south">
      <static>true</static>
      <pose>0 -3 0.1 0 0 0</pose>
      <link name="link">
        <collision name="col"><geometry><box><size>6 0.05 0.2</size></box></geometry></collision>
        <visual name="vis">
          <geometry><box><size>6 0.05 0.2</size></box></geometry>
          <material><ambient>0.3 0.3 0.3 1</ambient><diffuse>0.5 0.5 0.5 1</diffuse></material>
        </visual>
      </link>
    </model>

    <model name="wall_north">
      <static>true</static>
      <pose>0 3 0.1 0 0 0</pose>
      <link name="link">
        <collision name="col"><geometry><box><size>6 0.05 0.2</size></box></geometry></collision>
        <visual name="vis">
          <geometry><box><size>6 0.05 0.2</size></box></geometry>
          <material><ambient>0.3 0.3 0.3 1</ambient><diffuse>0.5 0.5 0.5 1</diffuse></material>
        </visual>
      </link>
    </model>

    <model name="wall_west">
      <static>true</static>
      <pose>-3 0 0.1 0 0 1.5708</pose>
      <link name="link">
        <collision name="col"><geometry><box><size>6 0.05 0.2</size></box></geometry></collision>
        <visual name="vis">
          <geometry><box><size>6 0.05 0.2</size></box></geometry>
          <material><ambient>0.3 0.3 0.3 1</ambient><diffuse>0.5 0.5 0.5 1</diffuse></material>
        </visual>
      </link>
    </model>

    <model name="wall_east">
      <static>true</static>
      <pose>3 0 0.1 0 0 1.5708</pose>
      <link name="link">
        <collision name="col"><geometry><box><size>6 0.05 0.2</size></box></geometry></collision>
        <visual name="vis">
          <geometry><box><size>6 0.05 0.2</size></box></geometry>
          <material><ambient>0.3 0.3 0.3 1</ambient><diffuse>0.5 0.5 0.5 1</diffuse></material>
        </visual>
      </link>
    </model>

    <!-- Interior obstacles -->
    <model name="box1">
      <static>true</static>
      <pose>-1.5 1.5 0.15 0 0 0</pose>
      <link name="link">
        <collision name="col"><geometry><box><size>0.3 0.3 0.3</size></box></geometry></collision>
        <visual name="vis">
          <geometry><box><size>0.3 0.3 0.3</size></box></geometry>
          <material><ambient>0.8 0.2 0.2 1</ambient><diffuse>0.8 0.2 0.2 1</diffuse></material>
        </visual>
      </link>
    </model>

    <model name="box2">
      <static>true</static>
      <pose>1.5 -1.5 0.15 0 0 0</pose>
      <link name="link">
        <collision name="col"><geometry><box><size>0.3 0.3 0.3</size></box></geometry></collision>
        <visual name="vis">
          <geometry><box><size>0.3 0.3 0.3</size></box></geometry>
          <material><ambient>0.2 0.2 0.8 1</ambient><diffuse>0.2 0.2 0.8 1</diffuse></material>
        </visual>
      </link>
    </model>

    <model name="box3">
      <static>true</static>
      <pose>1.5 1.5 0.15 0 0 0</pose>
      <link name="link">
        <collision name="col"><geometry><box><size>0.3 0.3 0.3</size></box></geometry></collision>
        <visual name="vis">
          <geometry><box><size>0.3 0.3 0.3</size></box></geometry>
          <material><ambient>0.2 0.8 0.2 1</ambient><diffuse>0.2 0.8 0.2 1</diffuse></material>
        </visual>
      </link>
    </model>

    <model name="box4">
      <static>true</static>
      <pose>-1.5 -1.5 0.15 0 0 0</pose>
      <link name="link">
        <collision name="col"><geometry><box><size>0.3 0.3 0.3</size></box></geometry></collision>
        <visual name="vis">
          <geometry><box><size>0.3 0.3 0.3</size></box></geometry>
          <material><ambient>0.8 0.8 0.2 1</ambient><diffuse>0.8 0.8 0.2 1</diffuse></material>
        </visual>
      </link>
    </model>

    <!-- Central column -->
    <model name="pillar">
      <static>true</static>
      <pose>0 0 0.25 0 0 0</pose>
      <link name="link">
        <collision name="col"><geometry><cylinder><radius>0.12</radius><length>0.5</length></cylinder></geometry></collision>
        <visual name="vis">
          <geometry><cylinder><radius>0.12</radius><length>0.5</length></cylinder></geometry>
          <material><ambient>0.6 0.4 0.2 1</ambient><diffuse>0.6 0.4 0.2 1</diffuse></material>
        </visual>
      </link>
    </model>

    <!-- ═══════════════════════════════════════════════════════════════════════
         TurtleBot3 Burger
         All link poses are relative to the model origin (= base_footprint).

         Correct positions from official turtlebot3_description URDF:
           base_joint:  xyz="0 0 0.010"
           wheel_left:  xyz="0  0.08 0.023" from base_link → abs z = 0.010+0.023 = 0.033
           wheel_right: xyz="0 -0.08 0.023" from base_link → abs z = 0.033
           caster:      xyz="-0.081 0 -0.004" from base_link → abs z = 0.010-0.004 = 0.006
           imu:         xyz="-0.032 0 0.068" from base_link → abs z = 0.078
           base_scan:   xyz="-0.032 0 0.172" from base_link → abs z = 0.182
           camera:      xyz="0.064 0 0.094" from base_link → abs z = 0.104
         ═══════════════════════════════════════════════════════════════════════ -->
    <model name="turtlebot3">
      <pose>0 -2 0 0 0 0</pose>

      <!-- base_footprint: virtual ground-contact reference frame -->
      <link name="base_footprint">
        <pose>0 0 0 0 0 0</pose>
        <inertial><mass>0.001</mass></inertial>
      </link>

      <!-- base_link: main chassis -->
      <link name="base_link">
        <pose>0 0 0.010 0 0 0</pose>
        <inertial>
          <mass>8.2573504e-01</mass>
          <inertia>
            <ixx>2.2124416e-03</ixx><ixy>-1.2294101e-05</ixy><ixz>3.4938785e-05</ixz>
            <iyy>2.1193702e-03</iyy><iyz>-5.0120904e-06</iyz>
            <izz>2.0064271e-03</izz>
          </inertia>
        </inertial>
        <collision name="base_collision">
          <!-- Offset matches official URDF: -0.032 from link origin, 0.070 height center -->
          <pose>-0.032 0 0.070 0 0 0</pose>
          <geometry><box><size>0.140 0.140 0.143</size></box></geometry>
        </collision>
        <visual name="base_visual">
          <pose>-0.032 0 0.070 0 0 0</pose>
          <geometry><box><size>0.140 0.140 0.143</size></box></geometry>
          <material><ambient>0.4 0.4 0.4 1</ambient><diffuse>0.5 0.5 0.5 1</diffuse></material>
        </visual>
      </link>

      <joint name="base_joint" type="fixed">
        <parent>base_footprint</parent><child>base_link</child>
      </joint>

      <!-- Left wheel: abs z = 0.033 = wheel_radius (wheels just touch ground) -->
      <link name="wheel_left_link">
        <pose>0 0.08 0.033 -1.5708 0 0</pose>
        <inertial>
          <mass>2.8498940e-02</mass>
          <inertia>
            <ixx>1.1175580e-05</ixx><ixy>-4.2369783e-11</ixy><ixz>-5.9381719e-09</ixz>
            <iyy>1.1192413e-05</iyy><iyz>-1.4400107e-11</iyz><izz>2.0712558e-05</izz>
          </inertia>
        </inertial>
        <collision name="col">
          <geometry><cylinder><radius>0.033</radius><length>0.018</length></cylinder></geometry>
          <surface><friction><ode><mu>100</mu><mu2>100</mu2></ode></friction></surface>
        </collision>
        <visual name="vis">
          <geometry><cylinder><radius>0.033</radius><length>0.018</length></cylinder></geometry>
          <material><ambient>0.2 0.2 0.2 1</ambient><diffuse>0.2 0.2 0.2 1</diffuse></material>
        </visual>
      </link>

      <joint name="wheel_left_joint" type="revolute">
        <parent>base_link</parent><child>wheel_left_link</child>
        <axis><xyz>0 0 1</xyz><limit><effort>1</effort><velocity>100</velocity></limit></axis>
      </joint>

      <!-- Right wheel: abs z = 0.033 -->
      <link name="wheel_right_link">
        <pose>0 -0.08 0.033 -1.5708 0 0</pose>
        <inertial>
          <mass>2.8498940e-02</mass>
          <inertia>
            <ixx>1.1175580e-05</ixx><ixy>-4.2369783e-11</ixy><ixz>-5.9381719e-09</ixz>
            <iyy>1.1192413e-05</iyy><iyz>-1.4400107e-11</iyz><izz>2.0712558e-05</izz>
          </inertia>
        </inertial>
        <collision name="col">
          <geometry><cylinder><radius>0.033</radius><length>0.018</length></cylinder></geometry>
          <surface><friction><ode><mu>100</mu><mu2>100</mu2></ode></friction></surface>
        </collision>
        <visual name="vis">
          <geometry><cylinder><radius>0.033</radius><length>0.018</length></cylinder></geometry>
          <material><ambient>0.2 0.2 0.2 1</ambient><diffuse>0.2 0.2 0.2 1</diffuse></material>
        </visual>
      </link>

      <joint name="wheel_right_joint" type="revolute">
        <parent>base_link</parent><child>wheel_right_link</child>
        <axis><xyz>0 0 1</xyz><limit><effort>1</effort><velocity>100</velocity></limit></axis>
      </joint>

      <!-- Caster: abs z = 0.006, ball joint, zero friction -->
      <link name="caster_back_link">
        <pose>-0.081 0 0.006 0 0 0</pose>
        <inertial>
          <mass>0.005</mass>
          <inertia><ixx>0.001</ixx><iyy>0.001</iyy><izz>0.001</izz></inertia>
        </inertial>
        <collision name="col">
          <geometry><sphere><radius>0.006</radius></sphere></geometry>
          <surface><friction><ode><mu>0</mu><mu2>0</mu2></ode></friction></surface>
        </collision>
        <visual name="vis">
          <geometry><sphere><radius>0.006</radius></sphere></geometry>
          <material><ambient>0.5 0.5 0.5 1</ambient></material>
        </visual>
      </link>

      <joint name="caster_back_joint" type="ball">
        <parent>base_link</parent><child>caster_back_link</child>
      </joint>

      <!-- IMU link: abs z = 0.010 + 0.068 = 0.078 -->
      <link name="imu_link">
        <pose>-0.032 0 0.078 0 0 0</pose>
        <inertial><mass>0.001</mass><inertia><ixx>0.00001</ixx><iyy>0.00001</iyy><izz>0.00001</izz></inertia></inertial>
        <sensor name="imu" type="imu">
          <always_on>true</always_on>
          <update_rate>200</update_rate>
          <topic>imu</topic>
          <gz_frame_id>imu_link</gz_frame_id>
        </sensor>
      </link>

      <joint name="imu_joint" type="fixed">
        <parent>base_link</parent><child>imu_link</child>
      </joint>

      <!-- LiDAR link: abs z = 0.010 + 0.172 = 0.182 (official turtlebot3 position) -->
      <link name="base_scan">
        <pose>-0.032 0 0.182 0 0 0</pose>
        <inertial>
          <mass>0.114</mass>
          <inertia><ixx>0.001</ixx><iyy>0.001</iyy><izz>0.001</izz></inertia>
        </inertial>
        <collision name="col">
          <geometry><cylinder><radius>0.055</radius><length>0.0315</length></cylinder></geometry>
        </collision>
        <visual name="vis">
          <geometry><cylinder><radius>0.055</radius><length>0.0315</length></cylinder></geometry>
          <material><ambient>0.1 0.1 0.1 1</ambient><diffuse>0.1 0.1 0.1 1</diffuse></material>
        </visual>

        <sensor name="lidar" type="gpu_lidar">
          <always_on>true</always_on>
          <visualize>true</visualize>
          <update_rate>10</update_rate>
          <ray>
            <scan>
              <horizontal>
                <samples>360</samples>
                <resolution>1</resolution>
                <min_angle>-3.14159265</min_angle>
                <max_angle>3.14159265</max_angle>
              </horizontal>
            </scan>
            <range>
              <min>0.12</min>
              <max>3.5</max>
              <resolution>0.015</resolution>
            </range>
            <noise>
              <type>gaussian</type>
              <mean>0.0</mean>
              <stddev>0.01</stddev>
            </noise>
          </ray>
          <topic>scan</topic>
          <gz_frame_id>base_scan</gz_frame_id>
        </sensor>
      </link>

      <joint name="scan_joint" type="fixed">
        <parent>base_link</parent><child>base_scan</child>
      </joint>

      <!-- Camera link: abs z = 0.010 + 0.094 = 0.104, front of robot -->
      <link name="camera_link">
        <pose>0.064 0 0.104 0 0 0</pose>
        <inertial>
          <mass>0.015</mass>
          <inertia><ixx>0.0001</ixx><iyy>0.0001</iyy><izz>0.0001</izz></inertia>
        </inertial>
        <collision name="col">
          <geometry><box><size>0.025 0.090 0.025</size></box></geometry>
        </collision>
        <visual name="vis">
          <geometry><box><size>0.025 0.090 0.025</size></box></geometry>
          <material><ambient>0.0 0.0 0.8 1</ambient><diffuse>0.0 0.0 0.8 1</diffuse></material>
        </visual>

        <sensor name="camera" type="camera">
          <always_on>true</always_on>
          <update_rate>10</update_rate>
          <camera>
            <horizontal_fov>1.3962634</horizontal_fov>
            <image>
              <width>640</width>
              <height>480</height>
              <format>R8G8B8</format>
            </image>
            <clip>
              <near>0.02</near>
              <far>300</far>
            </clip>
            <noise>
              <type>gaussian</type>
              <mean>0.0</mean>
              <stddev>0.007</stddev>
            </noise>
          </camera>
          <topic>camera/image_raw</topic>
          <gz_frame_id>camera_link</gz_frame_id>
        </sensor>
      </link>

      <joint name="camera_joint" type="fixed">
        <parent>base_link</parent><child>camera_link</child>
      </joint>

      <!-- Differential drive -->
      <plugin filename="gz-sim-diff-drive-system" name="gz::sim::systems::DiffDrive">
        <left_joint>wheel_left_joint</left_joint>
        <right_joint>wheel_right_joint</right_joint>
        <wheel_separation>0.160</wheel_separation>
        <wheel_radius>0.033</wheel_radius>
        <odom_publish_frequency>20</odom_publish_frequency>
        <topic>cmd_vel</topic>
        <odom_topic>odom</odom_topic>
        <tf_topic>tf</tf_topic>
        <frame_id>odom</frame_id>
        <child_frame_id>base_footprint</child_frame_id>
        <min_acceleration>-1</min_acceleration>
        <max_acceleration>1</max_acceleration>
      </plugin>

      <!-- Joint state publisher -->
      <plugin filename="gz-sim-joint-state-publisher-system" name="gz::sim::systems::JointStatePublisher">
        <topic>joint_states</topic>
        <joint_name>wheel_left_joint</joint_name>
        <joint_name>wheel_right_joint</joint_name>
      </plugin>

    </model>

  </world>
</sdf>
