<?xml version="1.0"?>
<!--
  TurtleBot3 Burger URDF for Gazebo Harmonic + NAV2 (ROS2 Humble)

  Kinematics and inertia match the official turtlebot3_description package.
  Gazebo plugins (DiffDrive, LiDAR 10Hz, IMU, Camera 10Hz) are embedded
  via <gazebo> tags so the robot can be spawned from this single file.
-->
<robot name="turtlebot3_burger">

  <!-- ── Base frames ──────────────────────────────────────────────────────── -->

  <link name="base_footprint"/>

  <joint name="base_joint" type="fixed">
    <parent link="base_footprint"/>
    <child link="base_link"/>
    <origin xyz="0 0 0.010" rpy="0 0 0"/>
  </joint>

  <link name="base_link">
    <inertial>
      <origin xyz="0 0 0" rpy="0 0 0"/>
      <mass value="8.2573504e-01"/>
      <inertia ixx="2.2124416e-03" ixy="-1.2294101e-05" ixz="3.4938785e-05"
               iyy="2.1193702e-03" iyz="-5.0120904e-06" izz="2.0064271e-03"/>
    </inertial>
    <!-- Collision box matches physical burger chassis -->
    <collision>
      <origin xyz="-0.032 0 0.070" rpy="0 0 0"/>
      <geometry><box size="0.140 0.140 0.143"/></geometry>
    </collision>
    <visual>
      <origin xyz="-0.032 0 0.070" rpy="0 0 0"/>
      <geometry><box size="0.140 0.140 0.143"/></geometry>
      <material name="light_black"><color rgba="0.4 0.4 0.4 1.0"/></material>
    </visual>
  </link>

  <!-- ── Wheels ────────────────────────────────────────────────────────────── -->

  <joint name="wheel_left_joint" type="continuous">
    <parent link="base_link"/>
    <child link="wheel_left_link"/>
    <origin xyz="0 0.08 0.023" rpy="-1.5708 0 0"/>
    <axis xyz="0 0 1"/>
  </joint>

  <link name="wheel_left_link">
    <inertial>
      <origin xyz="0 0 0"/>
      <mass value="2.8498940e-02"/>
      <inertia ixx="1.1175580e-05" ixy="-4.2369783e-11" ixz="-5.9381719e-09"
               iyy="1.1192413e-05" iyz="-1.4400107e-11" izz="2.0712558e-05"/>
    </inertial>
    <collision>
      <geometry><cylinder length="0.018" radius="0.033"/></geometry>
    </collision>
    <visual>
      <geometry><cylinder length="0.018" radius="0.033"/></geometry>
      <material name="dark"><color rgba="0.2 0.2 0.2 1.0"/></material>
    </visual>
  </link>

  <joint name="wheel_right_joint" type="continuous">
    <parent link="base_link"/>
    <child link="wheel_right_link"/>
    <origin xyz="0 -0.08 0.023" rpy="-1.5708 0 0"/>
    <axis xyz="0 0 1"/>
  </joint>

  <link name="wheel_right_link">
    <inertial>
      <origin xyz="0 0 0"/>
      <mass value="2.8498940e-02"/>
      <inertia ixx="1.1175580e-05" ixy="-4.2369783e-11" ixz="-5.9381719e-09"
               iyy="1.1192413e-05" iyz="-1.4400107e-11" izz="2.0712558e-05"/>
    </inertial>
    <collision>
      <geometry><cylinder length="0.018" radius="0.033"/></geometry>
    </collision>
    <visual>
      <geometry><cylinder length="0.018" radius="0.033"/></geometry>
      <material name="dark"><color rgba="0.2 0.2 0.2 1.0"/></material>
    </visual>
  </link>

  <!-- ── Caster (single, official position) ────────────────────────────────── -->

  <joint name="caster_back_joint" type="fixed">
    <parent link="base_link"/>
    <child link="caster_back_link"/>
    <origin xyz="-0.081 0 -0.004" rpy="-1.5708 0 0"/>
  </joint>

  <link name="caster_back_link">
    <inertial>
      <origin xyz="0 0 0"/>
      <mass value="0.005"/>
      <inertia ixx="0.001" ixy="0" ixz="0" iyy="0.001" iyz="0" izz="0.001"/>
    </inertial>
    <collision>
      <origin xyz="0 0.001 0" rpy="0 0 0"/>
      <geometry><box size="0.030 0.009 0.020"/></geometry>
    </collision>
  </link>

  <!-- ── IMU ───────────────────────────────────────────────────────────────── -->

  <joint name="imu_joint" type="fixed">
    <parent link="base_link"/>
    <child link="imu_link"/>
    <origin xyz="-0.032 0 0.068" rpy="0 0 0"/>
  </joint>

  <link name="imu_link">
    <inertial>
      <mass value="0.001"/>
      <inertia ixx="0.00001" ixy="0" ixz="0" iyy="0.00001" iyz="0" izz="0.00001"/>
    </inertial>
  </link>

  <!-- ── LiDAR ─────────────────────────────────────────────────────────────── -->
  <!-- Official position from turtlebot3_description scan_joint -->

  <joint name="scan_joint" type="fixed">
    <parent link="base_link"/>
    <child link="base_scan"/>
    <origin xyz="-0.032 0 0.172" rpy="0 0 0"/>
  </joint>

  <link name="base_scan">
    <inertial>
      <mass value="0.114"/>
      <origin xyz="0 0 0"/>
      <inertia ixx="0.001" ixy="0" ixz="0" iyy="0.001" iyz="0" izz="0.001"/>
    </inertial>
    <collision>
      <origin xyz="0 0 -0.0065" rpy="0 0 0"/>
      <geometry><cylinder length="0.0315" radius="0.055"/></geometry>
    </collision>
    <visual>
      <origin xyz="0 0 -0.0065" rpy="0 0 0"/>
      <geometry><cylinder length="0.0315" radius="0.055"/></geometry>
      <material name="dark"><color rgba="0.1 0.1 0.1 1.0"/></material>
    </visual>
  </link>

  <!-- ── Camera ────────────────────────────────────────────────────────────── -->
  <!-- Mounted at the front of the robot, facing forward -->

  <joint name="camera_joint" type="fixed">
    <parent link="base_link"/>
    <child link="camera_link"/>
    <origin xyz="0.064 0 0.094" rpy="0 0 0"/>
  </joint>

  <link name="camera_link">
    <inertial>
      <mass value="0.015"/>
      <origin xyz="0 0 0"/>
      <inertia ixx="0.0001" ixy="0" ixz="0" iyy="0.0001" iyz="0" izz="0.0001"/>
    </inertial>
    <collision>
      <geometry><box size="0.025 0.090 0.025"/></geometry>
    </collision>
    <visual>
      <geometry><box size="0.025 0.090 0.025"/></geometry>
      <material name="blue"><color rgba="0.0 0.0 0.8 1.0"/></material>
    </visual>
  </link>

  <!-- Standard ROS camera optical frame (Z forward, X right, Y down) -->
  <joint name="camera_optical_joint" type="fixed">
    <parent link="camera_link"/>
    <child link="camera_optical_frame"/>
    <origin xyz="0 0 0" rpy="-1.5708 0 -1.5708"/>
  </joint>

  <link name="camera_optical_frame"/>

  <!-- ═══════════════════════════════════════════════════════════════════════ -->
  <!-- Gazebo plugins                                                          -->
  <!-- ═══════════════════════════════════════════════════════════════════════ -->

  <!-- Differential drive (model-level plugin) -->
  <gazebo>
    <plugin filename="gz-sim-diff-drive-system" name="gz::sim::systems::DiffDrive">
      <left_joint>wheel_left_joint</left_joint>
      <right_joint>wheel_right_joint</right_joint>
      <wheel_separation>0.160</wheel_separation>
      <wheel_radius>0.033</wheel_radius>
      <odom_publish_frequency>20</odom_publish_frequency>
      <topic>cmd_vel</topic>
      <odom_topic>odom</odom_topic>
      <tf_topic>tf</tf_topic>
      <frame_id>odom</frame_id>
      <child_frame_id>base_footprint</child_frame_id>
      <min_acceleration>-1</min_acceleration>
      <max_acceleration>1</max_acceleration>
    </plugin>
  </gazebo>

  <!-- Joint state publisher (model-level plugin) -->
  <gazebo>
    <plugin filename="gz-sim-joint-state-publisher-system" name="gz::sim::systems::JointStatePublisher">
      <topic>joint_states</topic>
      <joint_name>wheel_left_joint</joint_name>
      <joint_name>wheel_right_joint</joint_name>
    </plugin>
  </gazebo>

  <!-- Zero friction on caster -->
  <gazebo reference="caster_back_link">
    <mu1>0.0</mu1>
    <mu2>0.0</mu2>
  </gazebo>

  <!-- LiDAR sensor (10 Hz, 360°) -->
  <gazebo reference="base_scan">
    <sensor name="lidar" type="gpu_lidar">
      <always_on>true</always_on>
      <visualize>true</visualize>
      <update_rate>10</update_rate>
      <ray>
        <scan>
          <horizontal>
            <samples>360</samples>
            <resolution>1</resolution>
            <min_angle>-3.14159265</min_angle>
            <max_angle>3.14159265</max_angle>
          </horizontal>
        </scan>
        <range>
          <min>0.12</min>
          <max>3.5</max>
          <resolution>0.015</resolution>
        </range>
        <noise>
          <type>gaussian</type>
          <mean>0.0</mean>
          <stddev>0.01</stddev>
        </noise>
      </ray>
      <topic>scan</topic>
    </sensor>
  </gazebo>

  <!-- IMU sensor (200 Hz) -->
  <gazebo reference="imu_link">
    <sensor name="imu" type="imu">
      <always_on>true</always_on>
      <update_rate>200</update_rate>
      <topic>imu</topic>
    </sensor>
  </gazebo>

  <!-- RGB Camera sensor (10 Hz, 640×480, 80° FOV) -->
  <gazebo reference="camera_link">
    <sensor name="camera" type="camera">
      <always_on>true</always_on>
      <update_rate>10</update_rate>
      <camera>
        <horizontal_fov>1.3962634</horizontal_fov>
        <image>
          <width>640</width>
          <height>480</height>
          <format>R8G8B8</format>
        </image>
        <clip>
          <near>0.02</near>
          <far>300</far>
        </clip>
        <noise>
          <type>gaussian</type>
          <mean>0.0</mean>
          <stddev>0.007</stddev>
        </noise>
      </camera>
      <topic>camera/image_raw</topic>
    </sensor>
  </gazebo>

</robot>
